Workbook

Sheet README
B2: Oracle Fusion Pod — Implementation Dependency & RACI Tracker
B3: Companion tracker to the agentic onboarding guide. Drives Provision -> Install -> Foundation -> Modules.
B5: How to use this workbook
B6: 1. Phase 0 – Install | C6: Tick off post-provisioning install & access steps before any functional setup.
B7: 2. Discovery | C7: Capture the design decisions (COA, ledger, LE/BU, security, data) with the client. These anchor everything.
B8: 3. Module Tracker | C8: The master list: 46 tasks across phases. Set Status + RACI owners + dates. Status drives the dashboard.
B9: 4. Dependencies | C9: Every prerequisite edge, so you can see what blocks what. 'Blocked?' flags tasks whose prereqs aren't Done.
B10: 5. SQL Validation | C10: Detect & validate (PASS/FAIL) BIP SQL per object; run before opening downstream modules.
B11: 6. Dashboard | C11: Live roll-up by pillar and phase from the Module Tracker.
B13: RACI legend | C13: R=Responsible (does the work) A=Accountable (owns outcome) C=Consulted I=Informed
B14: Status values | C14: Not Started / In Progress / Done / N/A / Blocked
B15: Golden rule | C15: Foundation (Phase 1) must be Done and validated before Phase 2+ modules begin. Re-keying it later = re-implementation.

Sheet 1. Phase 0 - Install
A1: Phase 0 — Post-Provisioning Install & Access
A3: # | B3: Step | C3: What it covers | D3: Done?
A4: 1 | B4: Receive pod details & service admin access | C4: Capture test & prod pod URLs, identity domain, and the initial service administrator credentials from the activation email. | D4: No
A5: 2 | B5: Configure identity (IAM/IDCS) & SSO | C5: Set up the identity domain, federation/SSO with the client IdP, password policy, and MFA. Provision the first implementation users. | D5: No
A6: 3 | B6: Security Console baseline | C6: Copy seeded roles to custom roles, set role hierarchy strategy, and define the data-security approach before provisioning functional users. | D6: No
A7: 4 | B7: Outbound email & notifications | C7: Configure email server / from-address, BI delivery, and approval notifications so workflows and reports can send. | D7: No
A8: 5 | B8: Environment strategy (Test ↔ Prod, P2T) | C8: Confirm number of environments, refresh (P2T) cadence, and how config moves (configuration packages / migration sets) test→prod. | D8: No
A9: 6 | B9: Enable offerings in Functional Setup Manager | C9: Turn on the offerings for in-scope pillars (Financials, Procurement, SCM, HCM, CX, etc.). This is the master switch that reveals setup tasks. | D9: No
A10: 7 | B10: Create implementation project & setup strategy | C10: Decide UI task-list vs export/import setup, define the implementation project, and assign setup task owners. | D10: No
A11: 8 | B11: Sandbox & extensibility strategy | C11: Establish sandbox naming/governance for page/object extensions and the publish workflow. | D11: No
A12: 9 | B12: Release readiness process | C12: Set the process for quarterly Fusion updates: read what's new, regression test in test pod, then apply to prod. | D12: No

Sheet 2. Discovery
A1: Discovery — Design Decisions (capture with client BEFORE config)
A3: Area | B3: Question | C3: Client Answer / Decision | D3: Decided By
A4: Program | B4: Which pillars are go-live wave 1 vs later?
A5: Program | B5: Target go-live date(s) and hard fiscal/regulatory deadlines?
A6: Program | B6: Legacy systems replaced and their data quality?
A7: Program | B7: Key integrations (bank, tax engine, CPQ, Eloqua, payroll)?
A8: Foundation (Common) · Chart of Accounts (segments & value sets) | B8: How many segments and what (Company, Cost Center, Account, Product, Intercompany, Future)?
A9: Foundation (Common) · Chart of Accounts (segments & value sets) | B9: Segment lengths & value set sizes?
A10: Foundation (Common) · Chart of Accounts (segments & value sets) | B10: Hierarchies/trees needed for reporting?
A11: Foundation (Common) · Chart of Accounts (segments & value sets) | B11: Natural account = account segment qualifier?
A12: Foundation (Common) · Primary Ledger (+ SLA method) | B12: One ledger or many (multi-country)?
A13: Foundation (Common) · Primary Ledger (+ SLA method) | B13: Accounting method (Standard Accrual)?
A14: Foundation (Common) · Primary Ledger (+ SLA method) | B14: Secondary ledger / reporting currency needed?
A15: Foundation (Common) · Primary Ledger (+ SLA method) | B15: Ledger set / balancing rules?
... A44: HCM · Workforce structures (Legal Employer, Depts, Jobs, Grades) | B44: Legal employers per country?

Sheet 3. Module Tracker
A1: Module Tracker — Status, RACI & Dependencies
A3: ID | B3: Phase | C3: Pillar | D3: Task | E3: Prerequisites | F3: Status | G3: Blocked? | H3: Responsible (R) | I3: Accountable (A) | J3: Consulted (C) | K3: Informed (I) | L3: Target Date | M3: Notes
A4: geo | B4: 1 | C4: Foundation (Common) | D4: Geographies (TCA) | E4: — | F4: Not Started | G4: Ready
A5: ent | B5: 1 | C5: Foundation (Common) | D5: Enterprise definition | E5: Geographies (TCA) | F5: Not Started | G5: =IF((IF(AND($F$4<>"Done",$F$4<>"N/A"),1,0))>0,"BLOCKED","Ready") -> BLOCKED
A6: cur | B6: 1 | C6: Foundation (Common) | D6: Currencies & conversion rates | E6: Enterprise definition | F6: Not Started | G6: =IF((IF(AND($F$5<>"Done",$F$5<>"N/A"),1,0))>0,"BLOCKED","Ready") -> BLOCKED
A7: coa | B7: 1 | C7: Foundation (Common) | D7: Chart of Accounts (segments & value sets) | E7: Currencies & conversion rates | F7: Not Started | G7: =IF((IF(AND($F$6<>"Done",$F$6<>"N/A"),1,0))>0,"BLOCKED","Ready") -> BLOCKED
A8: cal | B8: 1 | C8: Foundation (Common) | D8: Accounting calendar | E8: Currencies & conversion rates | F8: Not Started | G8: =IF((IF(AND($F$6<>"Done",$F$6<>"N/A"),1,0))>0,"BLOCKED","Ready") -> BLOCKED
A9: led | B9: 1 | C9: Foundation (Common) | D9: Primary Ledger (+ SLA method) | E9: Chart of Accounts (segments & value sets), Accounting calendar | F9: Not Started | G9: =IF((IF(AND($F$7<>"Done",$F$7<>"N/A"),1,0)+IF(AND($F$8<>"Done",$F$8<>"N/A"),1,0))>0,"BLOCKED","Ready") -> BLOCKED
A10: le | B10: 1 | C10: Foundation (Common) | D10: Legal Entities & jurisdictions | E10: Primary Ledger (+ SLA method) | F10: Not Started | G10: =IF((IF(AND($F$9<>"Done",$F$9<>"N/A"),1,0))>0,"BLOCKED","Ready") -> BLOCKED
A11: bu | B11: 1 | C11: Foundation (Common) | D11: Business Units & functions | E11: Legal Entities & jurisdictions | F11: Not Started | G11: =IF((IF(AND($F$10<>"Done",$F$10<>"N/A"),1,0))>0,"BLOCKED","Ready") -> BLOCKED
A12: setid | B12: 1 | C12: Foundation (Common) | D12: Reference Data Sets (SetID) | E12: Business Units & functions | F12: Not Started | G12: =IF((IF(AND($F$11<>"Done",$F$11<>"N/A"),1,0))>0,"BLOCKED","Ready") -> BLOCKED
A13: loc | B13: 1 | C13: Foundation (Common) | D13: Locations | E13: Enterprise definition, Geographies (TCA) | F13: Not Started | G13: =IF((IF(AND($F$5<>"Done",$F$5<>"N/A"),1,0)+IF(AND($F$4<>"Done",$F$4<>"N/A"),1,0))>0,"BLOCKED","Ready") -> BLOCKED
A14: sec | B14: 1 | C14: Foundation (Common) | D14: Security: roles, data roles, users | E14: Enterprise definition | F14: Not Started | G14: =IF((IF(AND($F$5<>"Done",$F$5<>"N/A"),1,0))>0,"BLOCKED","Ready") -> BLOCKED
A15: data_clean | B15: 2 | C15: Customer Data Cleansing | D15: Customer Data Cleansing & TCA load | E15: Geographies (TCA) | F15: Not Started | G15: =IF((IF(AND($F$4<>"Done",$F$4<>"N/A"),1,0))>0,"BLOCKED","Ready") -> BLOCKED
A16: cust | B16: 2 | C16: Customer Data Cleansing | D16: Customer master (Accounts & Sites) | E16: Customer Data Cleansing & TCA load, Business Units & functions | F16: Not Started | G16: =IF((IF(AND($F$15<>"Done",$F$15<>"N/A"),1,0)+IF(AND($F$11<>"Done",$F$11<>"N/A"),1,0))>0,"BLOCKED","Ready") -> BLOCKED
A17: fin_gl | B17: 2 | C17: ERP / Financials | D17: General Ledger | E17: Primary Ledger (+ SLA method), Security: roles, data roles, users | F17: Not Started | G17: =IF((IF(AND($F$9<>"Done",$F$9<>"N/A"),1,0)+IF(AND($F$14<>"Done",$F$14<>"N/A"),1,0))>0,"BLOCKED","Ready") -> BLOCKED
A18: fin_tax | B18: 2 | C18: ERP / Financials | D18: Tax | E18: Legal Entities & jurisdictions, Geographies (TCA) | F18: Not Started | G18: =IF((IF(AND($F$10<>"Done",$F$10<>"N/A"),1,0)+IF(AND($F$4<>"Done",$F$4<>"N/A"),1,0))>0,"BLOCKED","Ready") -> BLOCKED
A19: scm_sup | B19: 2 | C19: SCM / Procurement / Mfg | D19: Supplier model | E19: Business Units & functions, Security: roles, data roles, users | F19: Not Started | G19: =IF((IF(AND($F$11<>"Done",$F$11<>"N/A"),1,0)+IF(AND($F$14<>"Done",$F$14<>"N/A"),1,0))>0,"BLOCKED","Ready") -> BLOCKED
A20: scm_inv | B20: 2 | C20: SCM / Procurement / Mfg | D20: Inventory orgs & Item Master (PIM) | E20: Business Units & functions, Legal Entities & jurisdictions | F20: Not Started | G20: =IF((IF(AND($F$11<>"Done",$F$11<>"N/A"),1,0)+IF(AND($F$10<>"Done",$F$10<>"N/A"),1,0))>0,"BLOCKED","Ready") -> BLOCKED
A21: hcm_ws | B21: 2 | C21: HCM | D21: Workforce structures (Legal Employer, Depts, Jobs, Grades) | E21: Business Units & functions, Locations | F21: Not Started | G21: =IF((IF(AND($F$11<>"Done",$F$11<>"N/A"),1,0)+IF(AND($F$13<>"Done",$F$13<>"N/A"),1,0))>0,"BLOCKED","Ready") -> BLOCKED
A22: fin_cm | B22: 3 | C22: ERP / Financials | D22: Cash Management & Banks | E22: General Ledger | F22: Not Started | G22: =IF((IF(AND($F$17<>"Done",$F$17<>"N/A"),1,0))>0,"BLOCKED","Ready") -> BLOCKED
A23: fin_ap | B23: 3 | C23: ERP / Financials | D23: Payables (AP) | E23: General Ledger, Tax, Supplier model, Cash Management & Banks | F23: Not Started | G23: =IF((IF(AND($F$17<>"Done",$F$17<>"N/A"),1,0)+IF(AND($F$18<>"Done",$F$18<>"N/A"),1,0)+IF(AND($F$19<>"Done",$F$19<>"N/A"),1,0)+IF(AND($F$22<>"Done",$F$22<>"N/A"),1,0))>0,"BLOCKED","Ready") -> BLOCKED
A24: fin_ar | B24: 3 | C24: ERP / Financials | D24: Receivables (AR) | E24: General Ledger, Tax, Customer master (Accounts & Sites) | F24: Not Started | G24: =IF((IF(AND($F$17<>"Done",$F$17<>"N/A"),1,0)+IF(AND($F$18<>"Done",$F$18<>"N/A"),1,0)+IF(AND($F$16<>"Done",$F$16<>"N/A"),1,0))>0,"BLOCKED","Ready") -> BLOCKED
A25: fin_fa | B25: 3 | C25: ERP / Financials | D25: Fixed Assets (FA) | E25: General Ledger | F25: Not Started | G25: =IF((IF(AND($F$17<>"Done",$F$17<>"N/A"),1,0))>0,"BLOCKED","Ready") -> BLOCKED
A26: scm_price | B26: 3 | C26: SCM / Procurement / Mfg | D26: Pricing | E26: Inventory orgs & Item Master (PIM) | F26: Not Started | G26: =IF((IF(AND($F$20<>"Done",$F$20<>"N/A"),1,0))>0,"BLOCKED","Ready") -> BLOCKED
A27: scm_proc | B27: 3 | C27: SCM / Procurement / Mfg | D27: Purchasing & Self-Service Procurement | E27: Supplier model, Inventory orgs & Item Master (PIM) | F27: Not Started | G27: =IF((IF(AND($F$19<>"Done",$F$19<>"N/A"),1,0)+IF(AND($F$20<>"Done",$F$20<>"N/A"),1,0))>0,"BLOCKED","Ready") -> BLOCKED
A28: hcm_core | B28: 3 | C28: HCM | D28: Core HR (workers & assignments) | E28: Workforce structures (Legal Employer, Depts, Jobs, Grades), Security: roles, data roles, users | F28: Not Started | G28: =IF((IF(AND($F$21<>"Done",$F$21<>"N/A"),1,0)+IF(AND($F$14<>"Done",$F$14<>"N/A"),1,0))>0,"BLOCKED","Ready") -> BLOCKED
A29: cx_res | B29: 3 | C29: CX (Sales/Service/CPQ) | D29: CX Sales: Resources & Sales hierarchy | E29: Security: roles, data roles, users, Customer master (Accounts & Sites) | F29: Not Started | G29: =IF((IF(AND($F$14<>"Done",$F$14<>"N/A"),1,0)+IF(AND($F$16<>"Done",$F$16<>"N/A"),1,0))>0,"BLOCKED","Ready") -> BLOCKED
A30: cx_prod | B30: 3 | C30: CX (Sales/Service/CPQ) | D30: CX Sales: Products & Catalog | E30: Inventory orgs & Item Master (PIM) | F30: Not Started | G30: =IF((IF(AND($F$20<>"Done",$F$20<>"N/A"),1,0))>0,"BLOCKED","Ready") -> BLOCKED
A31: fin_exp | B31: 4 | C31: ERP / Financials | D31: Expenses | E31: Payables (AP), Core HR (workers & assignments) | F31: Not Started | G31: =IF((IF(AND($F$23<>"Done",$F$23<>"N/A"),1,0)+IF(AND($F$28<>"Done",$F$28<>"N/A"),1,0))>0,"BLOCKED","Ready") -> BLOCKED
A32: scm_om | B32: 4 | C32: SCM / Procurement / Mfg | D32: Order Management + Global Order Promising | E32: Inventory orgs & Item Master (PIM), Pricing, Customer master (Accounts & Sites), Receivables (AR) | F32: Not Started | G32: =IF((IF(AND($F$20<>"Done",$F$20<>"N/A"),1,0)+IF(AND($F$26<>"Done",$F$26<>"N/A"),1,0)+IF(AND($F$16<>"Done",$F$16<>"N/A"),1,0)+IF(AND($F$24<>"Done",$F$24<>"N/A"),1,0))>0,"BLOCKED","Ready") -> BLOCKED
A33: scm_cost | B33: 4 | C33: SCM / Procurement / Mfg | D33: Cost Management | E33: Inventory orgs & Item Master (PIM), General Ledger | F33: Not Started | G33: =IF((IF(AND($F$20<>"Done",$F$20<>"N/A"),1,0)+IF(AND($F$17<>"Done",$F$17<>"N/A"),1,0))>0,"BLOCKED","Ready") -> BLOCKED
A34: scm_mfg | B34: 4 | C34: SCM / Procurement / Mfg | D34: Manufacturing | E34: Inventory orgs & Item Master (PIM) | F34: Not Started | G34: =IF((IF(AND($F$20<>"Done",$F$20<>"N/A"),1,0))>0,"BLOCKED","Ready") -> BLOCKED
A35: hcm_abs | B35: 4 | C35: HCM | D35: Absence Management | E35: Core HR (workers & assignments) | F35: Not Started | G35: =IF((IF(AND($F$28<>"Done",$F$28<>"N/A"),1,0))>0,"BLOCKED","Ready") -> BLOCKED
A36: hcm_pay | B36: 4 | C36: HCM | D36: Payroll | E36: Core HR (workers & assignments) | F36: Not Started | G36: =IF((IF(AND($F$28<>"Done",$F$28<>"N/A"),1,0))>0,"BLOCKED","Ready") -> BLOCKED
A37: hcm_cmp | B37: 4 | C37: HCM | D37: Compensation & Benefits | E37: Core HR (workers & assignments) | F37: Not Started | G37: =IF((IF(AND($F$28<>"Done",$F$28<>"N/A"),1,0))>0,"BLOCKED","Ready") -> BLOCKED
A38: cx_terr | B38: 4 | C38: CX (Sales/Service/CPQ) | D38: CX Sales: Territories | E38: CX Sales: Resources & Sales hierarchy, Customer master (Accounts & Sites) | F38: Not Started | G38: =IF((IF(AND($F$29<>"Done",$F$29<>"N/A"),1,0)+IF(AND($F$16<>"Done",$F$16<>"N/A"),1,0))>0,"BLOCKED","Ready") -> BLOCKED
A39: cx_sales | B39: 4 | C39: CX (Sales/Service/CPQ) | D39: CX Sales: Leads, Opportunities, Forecasting | E39: CX Sales: Products & Catalog, CX Sales: Territories | F39: Not Started | G39: =IF((IF(AND($F$30<>"Done",$F$30<>"N/A"),1,0)+IF(AND($F$38<>"Done",$F$38<>"N/A"),1,0))>0,"BLOCKED","Ready") -> BLOCKED
A40: cx_svc | B40: 4 | C40: CX (Sales/Service/CPQ) | D40: Fusion Service (Service Requests) | E40: Customer master (Accounts & Sites), CX Sales: Products & Catalog | F40: Not Started | G40: =IF((IF(AND($F$16<>"Done",$F$16<>"N/A"),1,0)+IF(AND($F$30<>"Done",$F$30<>"N/A"),1,0))>0,"BLOCKED","Ready") -> BLOCKED
A41: mnt_maint | B41: 5 | C41: Maintenance & Quality | D41: Maintenance | E41: Inventory orgs & Item Master (PIM), Manufacturing | F41: Not Started | G41: =IF((IF(AND($F$20<>"Done",$F$20<>"N/A"),1,0)+IF(AND($F$34<>"Done",$F$34<>"N/A"),1,0))>0,"BLOCKED","Ready") -> BLOCKED
...

Sheet 4. Dependencies
A1: Dependency Edges (Task ← requires ← Prerequisite)
A3: Task ID | B3: Task | C3: Phase | D3: Requires (ID) | E3: Requires (Task)
A4: geo | B4: Geographies (TCA) | C4: 1 | D4: — | E4: (foundational — no prerequisites)
A5: ent | B5: Enterprise definition | C5: 1 | D5: geo | E5: Geographies (TCA)
A6: cur | B6: Currencies & conversion rates | C6: 1 | D6: ent | E6: Enterprise definition
A7: coa | B7: Chart of Accounts (segments & value sets) | C7: 1 | D7: cur | E7: Currencies & conversion rates
A8: cal | B8: Accounting calendar | C8: 1 | D8: cur | E8: Currencies & conversion rates
A9: led | B9: Primary Ledger (+ SLA method) | C9: 1 | D9: coa | E9: Chart of Accounts (segments & value sets)
A10: led | B10: Primary Ledger (+ SLA method) | C10: 1 | D10: cal | E10: Accounting calendar
A11: le | B11: Legal Entities & jurisdictions | C11: 1 | D11: led | E11: Primary Ledger (+ SLA method)
A12: bu | B12: Business Units & functions | C12: 1 | D12: le | E12: Legal Entities & jurisdictions
A13: setid | B13: Reference Data Sets (SetID) | C13: 1 | D13: bu | E13: Business Units & functions
A14: loc | B14: Locations | C14: 1 | D14: ent | E14: Enterprise definition
A15: loc | B15: Locations | C15: 1 | D15: geo | E15: Geographies (TCA)
... A83: icm_txn | B83: ICM: Transactions, Calculation & Payment | C83: 6 | D83: fin_ar | E83: Receivables (AR)

Sheet 5. SQL Validation
A1: SQL — Detect (does it exist?) & Validate (readiness). Run as BI Publisher data-model SQL.
A3: Phase | B3: Pillar | C3: Object | D3: Detect SQL (BIP) | E3: Validate / Readiness Rule
A4: 1 | B4: Foundation (Common) | C4: Geographies (TCA) | D4: SELECT 'Geographies' obj, COUNT(*) cnt FROM hz_geographies | E4: Geographies exist for every country used by LE/BU/customers
A5: 1 | B5: Foundation (Common) | C5: Enterprise definition | D5: SELECT 'Enterprise' obj, COUNT(*) cnt FROM hr_organization_units hou WHERE hou.organization_type='ENTERPRISE' | E5: Exactly one enterprise defined
A6: 1 | B6: Foundation (Common) | C6: Currencies & conversion rates | D6: SELECT 'Enabled Currencies' obj, COUNT(*) cnt FROM fnd_currencies WHERE enabled_flag='Y' | E6: Ledger currency + all transaction currencies enabled; rate types defined
A7: 1 | B7: Foundation (Common) | C7: Chart of Accounts (segments & value sets) | D7: SELECT 'COA Structures' obj, COUNT(*) cnt FROM gl_code_combinations WHERE rownum<2 UNION ALL SELECT 'Value Sets', COUNT(*) FROM fnd_vs_value_sets | E7: COA structure + instance defined, all segments mapped to value sets, qualifiers set
A8: 1 | B8: Foundation (Common) | C8: Accounting calendar | D8: SELECT 'Calendars' obj, COUNT(DISTINCT period_set_name) cnt FROM gl_periods | E8: Calendar covers conversion history + current + future periods
A9: 1 | B9: Foundation (Common) | C9: Primary Ledger (+ SLA method) | D9: SELECT 'Ledgers' obj, COUNT(*) cnt FROM gl_ledgers WHERE ledger_category_code='PRIMARY' | E9: Primary ledger complete and assigned; periods opened
A10: 1 | B10: Foundation (Common) | C10: Legal Entities & jurisdictions | D10: SELECT 'Legal Entities' obj, COUNT(*) cnt FROM xle_entity_profiles | E10: Every LE has a registration and is assigned to a ledger
A11: 1 | B11: Foundation (Common) | C11: Business Units & functions | D11: SELECT 'Business Units' obj, COUNT(*) cnt FROM fun_all_business_units_v | E11: Each BU has ledger + default LE + required business functions assigned
A12: 1 | B12: Foundation (Common) | C12: Reference Data Sets (SetID) | D12: SELECT 'Reference Sets' obj, COUNT(*) cnt FROM fnd_setid_sets | E12: Set determinants assigned for each BU and set-enabled object
A13: 1 | B13: Foundation (Common) | C13: Locations | D13: SELECT 'Locations' obj, COUNT(*) cnt FROM per_locations_legislative_g | E13: All operating sites defined with valid geography
A14: 1 | B14: Foundation (Common) | C14: Security: roles, data roles, users | D14: SELECT 'Active Users' obj, COUNT(*) cnt FROM per_users WHERE active_flag='Y' | E14: Admin + functional impl users provisioned with correct roles and data scope
A15: 2 | B15: Customer Data Cleansing | C15: Customer Data Cleansing & TCA load | D15: SELECT 'Parties' o,COUNT(*) c FROM hz_parties UNION ALL SELECT 'Cust Accounts',COUNT(*) FROM hz_cust_accounts | E15: Golden party set deduped, standardized, hierarchy built, ready to load
... A49: 6 | B49: ICM (Incentive Comp) | C49: ICM: Transactions, Calculation & Payment | D49: SELECT 'Comp Transactions' obj, COUNT(*) cnt FROM cn_tp_transactions_all WHERE rownum<2 | E49: Import → calculate → approve → pay tested with reconciled amounts

Sheet 6. Dashboard
B2: Implementation Dashboard
B4: Overall
B5: Total tasks | C5: =COUNTA('3. Module Tracker'!A4:A49) -> 46
B6: Done | C6: =COUNTIF('3. Module Tracker'!F4:F49,"Done")+COUNTIF('3. Module Tracker'!F4:F49,"N/A") -> 0
B7: In Progress | C7: =COUNTIF('3. Module Tracker'!F4:F49,"In Progress") -> 0
B8: Not Started | C8: =COUNTIF('3. Module Tracker'!F4:F49,"Not Started") -> 46
B9: Blocked (flagged) | C9: =COUNTIF('3. Module Tracker'!G4:G49,"BLOCKED") -> 45
B10: % Complete | C10: =IF(C5=0,0,C6/C5) -> 0
B12: By Pillar | G12: By Phase
B13: Pillar | C13: Total | D13: Done | E13: % Done | G13: Phase | H13: Total | I13: Done | J13: % Done
B14: Foundation (Common) | C14: =COUNTIF('3. Module Tracker'!C4:C49,$B14) -> 11 | D14: =COUNTIFS('3. Module Tracker'!C4:C49,$B14,'3. Module Tracker'!F4:F49,"Done")+COUNTIFS('3. Module Tracker'!C4:C49,$B14,'3. Module Tracker'!F4:F49,"N/A") -> 0 | E14: =IF(C14=0,0,D14/C14) -> 0 | G14: 1 | H14: =COUNTIF('3. Module Tracker'!B4:B49,$G14) -> 11 | I14: =COUNTIFS('3. Module Tracker'!B4:B49,$G14,'3. Module Tracker'!F4:F49,"Done")+COUNTIFS('3. Module Tracker'!B4:B49,$G14,'3. Module Tracker'!F4:F49,"N/A") -> 0 | J14: =IF(H14=0,0,I14/H14) -> 0
B15: Customer Data Cleansing | C15: =COUNTIF('3. Module Tracker'!C4:C49,$B15) -> 2 | D15: =COUNTIFS('3. Module Tracker'!C4:C49,$B15,'3. Module Tracker'!F4:F49,"Done")+COUNTIFS('3. Module Tracker'!C4:C49,$B15,'3. Module Tracker'!F4:F49,"N/A") -> 0 | E15: =IF(C15=0,0,D15/C15) -> 0 | G15: 2 | H15: =COUNTIF('3. Module Tracker'!B4:B49,$G15) -> 7 | I15: =COUNTIFS('3. Module Tracker'!B4:B49,$G15,'3. Module Tracker'!F4:F49,"Done")+COUNTIFS('3. Module Tracker'!B4:B49,$G15,'3. Module Tracker'!F4:F49,"N/A") -> 0 | J15: =IF(H15=0,0,I15/H15) -> 0
B16: ERP / Financials | C16: =COUNTIF('3. Module Tracker'!C4:C49,$B16) -> 7 | D16: =COUNTIFS('3. Module Tracker'!C4:C49,$B16,'3. Module Tracker'!F4:F49,"Done")+COUNTIFS('3. Module Tracker'!C4:C49,$B16,'3. Module Tracker'!F4:F49,"N/A") -> 0 | E16: =IF(C16=0,0,D16/C16) -> 0 | G16: 3 | H16: =COUNTIF('3. Module Tracker'!B4:B49,$G16) -> 9 | I16: =COUNTIFS('3. Module Tracker'!B4:B49,$G16,'3. Module Tracker'!F4:F49,"Done")+COUNTIFS('3. Module Tracker'!B4:B49,$G16,'3. Module Tracker'!F4:F49,"N/A") -> 0 | J16: =IF(H16=0,0,I16/H16) -> 0
B17: SCM / Procurement / Mfg | C17: =COUNTIF('3. Module Tracker'!C4:C49,$B17) -> 7 | D17: =COUNTIFS('3. Module Tracker'!C4:C49,$B17,'3. Module Tracker'!F4:F49,"Done")+COUNTIFS('3. Module Tracker'!C4:C49,$B17,'3. Module Tracker'!F4:F49,"N/A") -> 0 | E17: =IF(C17=0,0,D17/C17) -> 0 | G17: 4 | H17: =COUNTIF('3. Module Tracker'!B4:B49,$G17) -> 10 | I17: =COUNTIFS('3. Module Tracker'!B4:B49,$G17,'3. Module Tracker'!F4:F49,"Done")+COUNTIFS('3. Module Tracker'!B4:B49,$G17,'3. Module Tracker'!F4:F49,"N/A") -> 0 | J17: =IF(H17=0,0,I17/H17) -> 0
B18: Maintenance & Quality | C18: =COUNTIF('3. Module Tracker'!C4:C49,$B18) -> 2 | D18: =COUNTIFS('3. Module Tracker'!C4:C49,$B18,'3. Module Tracker'!F4:F49,"Done")+COUNTIFS('3. Module Tracker'!C4:C49,$B18,'3. Module Tracker'!F4:F49,"N/A") -> 0 | E18: =IF(C18=0,0,D18/C18) -> 0 | G18: 5 | H18: =COUNTIF('3. Module Tracker'!B4:B49,$G18) -> 7 | I18: =COUNTIFS('3. Module Tracker'!B4:B49,$G18,'3. Module Tracker'!F4:F49,"Done")+COUNTIFS('3. Module Tracker'!B4:B49,$G18,'3. Module Tracker'!F4:F49,"N/A") -> 0 | J18: =IF(H18=0,0,I18/H18) -> 0
B19: HCM | C19: =COUNTIF('3. Module Tracker'!C4:C49,$B19) -> 5 | D19: =COUNTIFS('3. Module Tracker'!C4:C49,$B19,'3. Module Tracker'!F4:F49,"Done")+COUNTIFS('3. Module Tracker'!C4:C49,$B19,'3. Module Tracker'!F4:F49,"N/A") -> 0 | E19: =IF(C19=0,0,D19/C19) -> 0 | G19: 6 | H19: =COUNTIF('3. Module Tracker'!B4:B49,$G19) -> 2 | I19: =COUNTIFS('3. Module Tracker'!B4:B49,$G19,'3. Module Tracker'!F4:F49,"Done")+COUNTIFS('3. Module Tracker'!B4:B49,$G19,'3. Module Tracker'!F4:F49,"N/A") -> 0 | J19: =IF(H19=0,0,I19/H19) -> 0
B20: CX (Sales/Service/CPQ) | C20: =COUNTIF('3. Module Tracker'!C4:C49,$B20) -> 6 | D20: =COUNTIFS('3. Module Tracker'!C4:C49,$B20,'3. Module Tracker'!F4:F49,"Done")+COUNTIFS('3. Module Tracker'!C4:C49,$B20,'3. Module Tracker'!F4:F49,"N/A") -> 0 | E20: =IF(C20=0,0,D20/C20) -> 0
B21: CX Subscriptions | C21: =COUNTIF('3. Module Tracker'!C4:C49,$B21) -> 1 | D21: =COUNTIFS('3. Module Tracker'!C4:C49,$B21,'3. Module Tracker'!F4:F49,"Done")+COUNTIFS('3. Module Tracker'!C4:C49,$B21,'3. Module Tracker'!F4:F49,"N/A") -> 0 | E21: =IF(C21=0,0,D21/C21) -> 0
B22: CX Marketing & Eloqua | C22: =COUNTIF('3. Module Tracker'!C4:C49,$B22) -> 1 | D22: =COUNTIFS('3. Module Tracker'!C4:C49,$B22,'3. Module Tracker'!F4:F49,"Done")+COUNTIFS('3. Module Tracker'!C4:C49,$B22,'3. Module Tracker'!F4:F49,"N/A") -> 0 | E22: =IF(C22=0,0,D22/C22) -> 0
B23: PRM (Partners) | C23: =COUNTIF('3. Module Tracker'!C4:C49,$B23) -> 1 | D23: =COUNTIFS('3. Module Tracker'!C4:C49,$B23,'3. Module Tracker'!F4:F49,"Done")+COUNTIFS('3. Module Tracker'!C4:C49,$B23,'3. Module Tracker'!F4:F49,"N/A") -> 0 | E23: =IF(C23=0,0,D23/C23) -> 0
B24: ICM (Incentive Comp) | C24: =COUNTIF('3. Module Tracker'!C4:C49,$B24) -> 3 | D24: =COUNTIFS('3. Module Tracker'!C4:C49,$B24,'3. Module Tracker'!F4:F49,"Done")+COUNTIFS('3. Module Tracker'!C4:C49,$B24,'3. Module Tracker'!F4:F49,"N/A") -> 0 | E24: =IF(C24=0,0,D24/C24) -> 0
